Workbook

Sheet GCHCFS & Total Direct Exp.
A1: Government and Compulsory Health Care Financing Schemes (GCHCFS) refer to the health financing schemes that come from the direct government budget allocations, compulsory social or compulsory private health insurance schemes, or mandatory medical saving accounts
A2: Out-of-pocket (OOP) Payments is a type of financing scheme where households pay out of their pocket for the medical service
A3: Country | B3: Latest Data Year | C3: Population, 2024 | D3: Currency | E3: GCHCFS Expenditure (LCU) | F3: PPP Conversion Factor (from World Bank) | G3: PPP USD | H3: OOP Expenditure | I3: Total Direct Cancer Exp (GCHCFS+OOP) | J3: Per Capita | K3: Incidence 2024 (GLOBACAN 2024) | L3: Per-Case | M3: Comments
A4: Afghanistan | B4: 2021 | C4: 42647490 | D4: US Dollars | E4: =274634.09*82*1.0325 -> 23251895 | F4: 13.23 | G4: =E4/F4*0.228 -> 400712.93 | H4: =1757512.867*0.772 -> 1356799.9 | I4: =H4+G4 -> 1757512.9 | J4: =I4/C4 -> 0.04121023 | K4: 26268 | L4: =I4/K4 -> 66.906992 | M4: 2021 USD expenditure was turned into local afghani, inflated to 2024, and turned into $PPP. The value in E3 is already converted; the original value is: 274634.09 USD in 2021 (ehoch includes OOP and GCHCFS)
A5: Armenia | B5: 2024 | C5: 3033500 | D5: Armenian Dram | E5: 12958405888 | F5: 147.23111 | G5: =E5/F5 -> 88014050 | H5: =(G5*'OOP Exp.'!C4)/(100-'OOP Exp.'!C4) -> 3.520562e+08 | I5: =H5+G5 -> 4.4007025e+08 | J5: =I5/C5 -> 145.07013 | K5: 10718 | L5: =I5/K5 -> 41058.99 | M5: For Armenia, OOP payments are officially reported on a disease level, including cancer. However, we also use the data from the GHED database, which totals 80%.
A6: Azerbaijan | B6: 2024 | C6: 10202830 | D6: Azerbaijani Manat | E6: 48300000 | F6: 0.49354479 | G6: =E6/F6 -> 97863458 | H6: =(G6*'OOP Exp.'!C5)/(100-'OOP Exp.'!C5) -> 1.8174642e+08 | I6: =H6+G6 -> 2.7960988e+08 | J6: =I6/C6 -> 27.40513 | K6: 15251 | L6: =I6/K6 -> 18333.872
A7: Belarus | B7: 2015 | C7: 9132629 | D7: Belarusian ruble | E7: =11790000000*0.046 -> 542340000 | F7: 0.81794506 | G7: =E7/F7 -> 6.6305187e+08 | H7: =(G7*'OOP Exp.'!C6)/(100-'OOP Exp.'!C6) -> 2.578535e+08 | I7: =H7+G7 -> 9.2090537e+08 | J7: =I7/C7 -> 100.83683 | K7: 46420 | L7: =I7/K7 -> 19838.547
A8: Estonia | B8: 2024 | C8: 1372341 | D8: Euro | E8: 293014944 | F8: 0.583732 | G8: =E8/F8 -> 5.0196827e+08 | H8: =(G8*'OOP Exp.'!C7)/(100-'OOP Exp.'!C7) -> 1.334346e+08 | I8: =H8+G8 -> 6.3540288e+08 | J8: =I8/C8 -> 463.00655 | K8: 8363 | L8: =I8/K8 -> 75977.864
A9: Georgia | B9: 2024 | C9: 3699557 | D9: Georgian Lari | E9: 2.8414724e+08 | F9: 0.88895531 | G9: =E9/F9 -> 3.1964176e+08 | H9: =(G9*'OOP Exp.'!C8)/(100-'OOP Exp.'!C8) -> 4.5997228e+08 | I9: =H9+G9 -> 7.7961404e+08 | J9: =I9/C9 -> 210.73173 | K9: 16063 | L9: =I9/K9 -> 48534.772
A10: Kazakhstan | B10: 2024 | C10: 20592571 | D10: Kazakh Tenge | E10: =32508963000+161429380000 -> 193938343000 | F10: 162.33408 | G10: =E10/F10 -> 1.1946865e+09 | H10: =(G10*'OOP Exp.'!C9)/(100-'OOP Exp.'!C9) -> 4.6460032e+08 | I10: =H10+G10 -> 1.6592869e+09 | J10: =I10/C10 -> 80.576965 | K10: 29851 | L10: =I10/K10 -> 55585.638
A11: Kyrgyzstan | B11: 2024 | C11: 7221868 | D11: Kyrgyz Som | E11: =176000000+246600000*2+10777200 -> 679977200 | F11: 26.324008 | G11: =E11/F11 -> 25831067 | H11: =(G11*'OOP Exp.'!C10)/(100-'OOP Exp.'!C10) -> 18705255 | I11: =H11+G11 -> 44536322 | J11: =I11/C11 -> 6.1668701 | K11: 8902 | L11: =I11/K11 -> 5002.9569
A12: Latvia | B12: 2024 | C12: 1866124 | D12: Euro | E12: 175691289 | F12: 0.492149 | G12: =E12/F12 -> 3.56988e+08 | H12: =(G12*'OOP Exp.'!C11)/(100-'OOP Exp.'!C11) -> 1.9222431e+08 | I12: =H12+G12 -> 5.4921231e+08 | J12: =I12/C12 -> 294.30644 | K12: 11317 | L12: =I12/K12 -> 48529.85
A13: Lithuania | B13: 2024 | C13: 2888278 | D13: Euro | E13: 404500000 | F13: 0.498947 | G13: =E13/F13 -> 8.1070735e+08 | H13: =(G13*'OOP Exp.'!C12)/(100-'OOP Exp.'!C12) -> 3.6423084e+08 | I13: =H13+G13 -> 1.1749382e+09 | J13: =I13/C13 -> 406.79539 | K13: 16368 | L13: =I13/K13 -> 71782.636
A14: Republic of Moldova | B14: 2024 | C14: 2402306 | D14: Moldovan Lei | E14: =552520230+4790500 -> 557310730 | F14: 7.241163 | G14: =E14/F14 -> 76964257 | H14: =(G14*'OOP Exp.'!C13)/(100-'OOP Exp.'!C13) -> 28466232 | I14: =H14+G14 -> 1.0543049e+08 | J14: =I14/C14 -> 43.887202 | K14: 11349 | L14: =I14/K14 -> 9289.8484
A15: Russian Federation | B15: 2024 | C15: 143533851 | D15: Russian Rubles | E15: =(386.6+0.04951318078)*1000000000 -> 3.8664951e+11 | F15: 29.062975 | G15: =E15/F15 -> 1.3303852e+10 | H15: =(G15*'OOP Exp.'!C14)/(100-'OOP Exp.'!C14) -> 5.1737202e+09 | I15: =H15+G15 -> 1.8477572e+10 | J15: =I15/C15 -> 128.7332 | K15: 633830 | L15: =I15/K15 -> 29152.253
A16: Slovakia | B16: 2024 | C16: 5422069 | D16: Euro | E16: 5.2442702e+08 | F16: 0.512025 | G16: =E16/F16 -> 1.0242215e+09 | H16: =(G16*'OOP Exp.'!C15)/(100-'OOP Exp.'!C15) -> 2.5605538e+08 | I16: =H16+G16 -> 1.2802769e+09 | J16: =I16/C16 -> 236.12331 | K16: 31384 | L16: =I16/K16 -> 40793.936
A17: Slovenia | B17: 2024 | C17: 2127400 | D17: Euro | E17: 4.7175657e+08 | F17: 0.557128 | G17: =E17/F17 -> 8.4676514e+08 | H17: =(G17*'OOP Exp.'!C16)/(100-'OOP Exp.'!C16) -> 1.1546797e+08 | I17: =H17+G17 -> 9.6223311e+08 | J17: =I17/C17 -> 452.30474 | K17: 14264 | L17: =I17/K17 -> 67458.855
A18: Tajikistan | B18: 2024 | C18: 10590927 | D18: Tajik Somoni | E18: 188400000 | F18: 2.6793113 | G18: =E18/F18 -> 70316578 | H18: =(G18*'OOP Exp.'!C17)/(100-'OOP Exp.'!C17) -> 1.1472705e+08 | I18: =H18+G18 -> 1.8504363e+08 | J18: =I18/C18 -> 17.471901 | K18: 8222 | L18: =I18/K18 -> 22505.914 | M18: Data is modelled based on 7 countries
A19: Turkmenistan | B19: 2024 | C19: 7494498 | D19: Turkmen Manat | E19: 137495829 | F19: 1.511891 | G19: =E19/F19 -> 90942950 | H19: =(G19*'OOP Exp.'!C18)/(100-'OOP Exp.'!C18) -> 3.0446118e+08 | I19: =H19+G19 -> 3.9540413e+08 | J19: =I19/C19 -> 52.759255 | K19: 7659 | L19: =I19/K19 -> 51626.078 | M19: Data is modelled based on 7 countries
A20: Ukraine | B20: 2024 | C20: 37860221 | D20: Ukrainan Griven | E20: 7.4492043e+09 | F20: 11.6654 | G20: =E20/F20 -> 6.3857255e+08 | H20: =(G20*'OOP Exp.'!C19)/(100-'OOP Exp.'!C19) -> 5.2246845e+08 | I20: =H20+G20 -> 1.161041e+09 | J20: =I20/C20 -> 30.666514 | K20: 153699 | L20: =I20/K20 -> 7553.9919
A21: Uzbekistan | B21: 2024 | C21: 36361859 | D21: Uzbek Sum | E21: 164300000000 | F21: 3367.6439 | G21: =E21/F21 -> 48787818 | H21: =(G21*'OOP Exp.'!C20)/(100-'OOP Exp.'!C20) -> 86733899 | I21: =H21+G21 -> 1.3552172e+08 | J21: =I21/C21 -> 3.7270294 | K21: 38465 | L21: =I21/K21 -> 3523.2475
A22: The sources of expenditure and currency conversion data and forumals are written in the main text and supplementary material.

Sheet Longitudinal Exp.
A1: Government and Compulsory Health Care Financing Schemes (GCHCFS) refer to the health financing schemes that come from the direct government budget allocations, compulsory social or compulsory private health insurance schemes, or mandatory medical saving accounts. Here, we inflate all years to 2024 for data comparability between years. The data is also transformed into PPP$ for comparability between the countries.
A2: Armenia
A3: Year | B3: Expenditure (Dram) | C3: 2019→2020 | D3: 2020→2021 | E3: 2021→2022 | F3: 2022→2023 | G3: 2023→2024 | H3: Inflated | I3: PPP factor | J3: PPP $ | K3: Population | L3: Adj for Population
A4: 2021 | B4: =(5330+87+200)*1000000 -> 5617000000 | C4: 1.0180659 | D4: 1.0180659 | E4: 1.0798588 | F4: 1.0310028 | G4: 1.0140106 | H4: =B4*E4*F4*G4 -> 6.3412331e+09 | I4: 147.23111 | J4: =H4/I4 -> 43069928 | K4: 2962300 | L4: =J4/K4 -> 14.539354
A5: 2022 | B5: =(9474+2889)*1000000 -> 12363000000 | C5: 1.0180659 | D5: 1.0180659 | E5: 1.0798588 | F5: 1.0310028 | G5: 1.0140106 | H5: =B5*F5*G5 -> 1.292487e+10 | I5: 147.23111 | J5: =H5/I5 -> 87786276 | K5: 2969200 | L5: =J5/K5 -> 29.565632
A6: 2023 | B6: =13412*1000000 -> 13412000000 | C6: 1.0180659 | D6: 1.0180659 | E6: 1.0798588 | F6: 1.0310028 | G6: 1.0140106 | H6: =B6*G6 -> 1.359991e+10 | I6: 147.23111 | J6: =H6/I6 -> 92371176 | K6: 2964300 | L6: =J6/K6 -> 31.16121
A7: 2024 | B7: 12958405888 | C7: 1.0180659 | D7: 1.0180659 | E7: 1.0798588 | F7: 1.0310028 | G7: 1.0140106 | H7: =B7 -> 12958405888 | I7: 147.23111 | J7: =H7/I7 -> 88014050 | K7: 3033500 | L7: =J7/K7 -> 29.014027
A9: Slovakia
A10: Year | B10: Expenditure (EUR) | C10: 2019→2020 | D10: 2020→2021 | E10: 2021→2022 | F10: 2022→2023 | G10: 2023→2024 | H10: Inflated | I10: PPP factor | J10: PPP $ | K10: Population | L10: Adj for Population
A11: 2020 | B11: 397979172 | C11: 1.0240778 | D11: 1.0224408 | E11: 1.0733388 | F11: 1.1002459 | G11: 1.033937 | H11: =B11*D11*E11*F11*G11 -> 4.9684299e+08 | I11: 0.512025 | J11: =H11/I11 -> 9.7034908e+08 | K11: 5458827 | L11: =J11/K11 -> 177.7578
A12: 2021 | B12: 461764780 | C12: 1.0240778 | D12: 1.0224408 | E12: 1.0733388 | F12: 1.1002459 | G12: 1.033937 | H12: =B12*E12*F12*G12 -> 5.6382125e+08 | I12: 0.512025 | J12: =H12/I12 -> 1.1011596e+09 | K12: 5447247 | L12: =J12/K12 -> 202.14975
A13: 2022 | B13: 498861346 | C13: 1.0240778 | D13: 1.0224408 | E13: 1.0733388 | F13: 1.1002459 | G13: 1.033937 | H13: =B13*F13*G13 -> 5.6749714e+08 | I13: 0.512025 | J13: =H13/I13 -> 1.1083387e+09 | K13: 5431752 | L13: =J13/K13 -> 204.04811
A14: 2023 | B14: 5.2442702e+08 | C14: 1.0240778 | D14: 1.0224408 | E14: 1.0733388 | F14: 1.1002459 | G14: 1.033937 | H14: =B14*G14 -> 5.4222449e+08 | I14: 0.512025 | J14: =H14/I14 -> 1.0589805e+09 | K14: 5426740 | L14: =J14/K14 -> 195.14119
A16: Kazakhstan
A17: Year | B17: Expenditure (Tenge) | C17: 2019→2020 | D17: 2020→2021 | E17: 2021→2022 | F17: 2022→2023 | G17: 2023→2024 | H17: Inflated | I17: PPP factor | J17: PPP $ | K17: Population | L17: Adj for Population
A18: 2019 | B18: 50600000000 | C18: 1.0421086 | D18: 1.1393008 | E18: 1.1976901 | F18: 1.0952225 | G18: 1.0899332 | H18: =B18*C18*D18*E18*F18*G18 -> 8.5891172e+10 | I18: 162.33408 | J18: =H18/I18 -> 5.2910129e+08 | K18: 19209555 | L18: =J18/K18 -> 27.543652
A19: 2020 | B19: 65200000000 | C19: 1.0421086 | D19: 1.1393008 | E19: 1.1976901 | F19: 1.0952225 | G19: 1.0899332 | H19: =B19*D19*E19*F19*G19 -> 1.0620199e+11 | I19: 162.33408 | J19: =H19/I19 -> 6.5421866e+08 | K19: 19482117 | L19: =J19/K19 -> 33.580471
A20: 2021 | B20: 82200000000 | C20: 1.0421086 | D20: 1.1393008 | E20: 1.1976901 | F20: 1.0952225 | G20: 1.0899332 | H20: =B20*E20*F20*G20 -> 1.1752181e+11 | I20: 162.33408 | J20: =H20/I20 -> 7.2395032e+08 | K20: 19743603 | L20: =J20/K20 -> 36.667589
A21: 2022 | B21: 121329000000 | C21: 1.0421086 | D21: 1.1393008 | E21: 1.1976901 | F21: 1.0952225 | G21: 1.0899332 | H21: =B21*F21*G21 -> 1.4483277e+11 | I21: 162.33408 | J21: =H21/I21 -> 8.9218953e+08 | K21: 20034609 | L21: =J21/K21 -> 44.532415
A22: 2023 | B22: 183400000000 | C22: 1.0421086 | D22: 1.1393008 | E22: 1.1976901 | F22: 1.0952225 | G22: 1.0899332 | H22: =B22*G22 -> 199893741544 | I22: 162.33408 | J22: =H22/I22 -> 1.2313726e+09 | K22: 20330104 | L22: =J22/K22 -> 60.568928
A23: 2024 | B23: 193938000000 | C23: 1.0421086 | D23: 1.1393008 | E23: 1.1976901 | F23: 1.0952225 | G23: 1.0899332 | H23: =B23 -> 193938000000 | I23: 162.33408 | J23: =H23/I23 -> 1.1946844e+09 | K23: 20592571 | L23: =J23/K23 -> 58.015312
A24: 2025 | B24: =174149278000+36610165000 -> 210759443000 | C24: 1.0421086 | D24: 1.1393008 | E24: 1.1976901 | F24: 1.0952225 | G24: 1.0899332 | H24: =B24/1.09605109 -> 1.922898e+11 | I24: 162.33408 | J24: =H24/I24 -> 1.1845313e+09 | K24: 20843754 | L24: =J24/K24 -> 56.829076 | M24: 1.0960511
A26: Russia
A27: Year | B27: Expenditure (Ruble) | C27: 2019→2020 | D27: 2020→2021 | E27: 2021→2022 | F27: 2022→2023 | G27: 2023→2024 | H27: Inflated | I27: PPP factor | J27: PPP $ | K27: Population | L27: Adj for Population
A28: 2019 | B28: =200.4*1000000000 -> 200400000000 | C28: 1.0089825 | D28: 1.182091 | E28: 1.1822961 | F28: 1.0665889 | G28: 1.1065285 | H28: =B28*C28*D28*E28*F28*G28 -> 3.3351714e+11 | I28: 29.062975 | J28: =H28/I28 -> 1.1475671e+10 | K28: 145453291 | L28: =J28/K28 -> 78.895919
A29: 2020 | B29: =271.3*1000000000 -> 271300000000 | C29: 1.0089825 | D29: 1.182091 | E29: 1.1822961 | F29: 1.0665889 | G29: 1.1065285 | H29: =B29*D29*E29*F29*G29 -> 4.4749338e+11 | I29: 29.062975 | J29: =H29/I29 -> 1.539737e+10 | K29: 145245148 | L29: =J29/K29 -> 106.00953
A30: 2021 | B30: =307.8*1000000000 -> 307800000000 | C30: 1.0089825 | D30: 1.182091 | E30: 1.1822961 | F30: 1.0665889 | G30: 1.1065285 | H30: =B30*E30*F30*G30 -> 4.2949145e+11 | I30: 29.062975 | J30: =H30/I30 -> 1.4777959e+10 | K30: 144746762 | L30: =J30/K30 -> 102.09526
A31: 2022 | B31: =327.1*1000000000 -> 327100000000 | C31: 1.0089825 | D31: 1.182091 | E31: 1.1822961 | F31: 1.0665889 | G31: 1.1065285 | H31: =B31*F31*G31 -> 3.86047e+11 | I31: 29.062975 | J31: =H31/I31 -> 1.3283121e+10 | K31: 144236933 | L31: =J31/K31 -> 92.092368
A32: 2023 | B32: =369.5248*1000000000 -> 369524800000 | C32: 1.0089825 | D32: 1.182091 | E32: 1.1822961 | F32: 1.0665889 | G32: 1.1065285 | H32: =B32*G32 -> 4.0888971e+11 | I32: 29.062975 | J32: =H32/I32 -> 1.4069094e+10 | K32: 143826130 | L32: =J32/K32 -> 97.820149
A33: 2024 | B33: =386.6*1000000000 -> 386600000000 | C33: 1.0089825 | D33: 1.182091 | E33: 1.1822961 | F33: 1.0665889 | G33: 1.1065285 | H33: =B33 -> 386600000000 | I33: 29.062975 | J33: =H33/I33 -> 1.3302148e+10 | K33: 143669648 | L33: =J33/K33 -> 92.588438
A34: 2025 | B34: =434.5*1000000000 -> 434500000000 | C34: 1.0089825 | D34: 1.182091 | E34: 1.1822961 | F34: 1.0665889 | G34: 1.1065285 | H34: =B34/1.04852053 -> 4.1439341e+11 | I34: 29.062975 | J34: =H34/I34 -> 1.4258465e+10 | K34: 143513328 | L34: =J34/K34 -> 99.352899 | M34: 1.04852053 is an inflation factor from 2024 to 2025. Since the base year is 2024, we convert 2025 expenditure to 2024
A36: Moldova
A37: Year | B37: Expenditure (Griven) | C37: 2019→2020 | D37: 2020→2021 | E37: 2021→2022 | F37: 2022→2023 | G37: 2023→2024 | H37: Inflated | I37: PPP factor | J37: PPP $ | K37: Population | L37: Adj for Population
A38: 2020 | B38: 2.9625781e+08 | C38: 1.0557501 | D38: 1.0638173 | E38: 1.1891497 | F38: 1.0929076 | G38: 1.0642523 | H38: =B38*D38*E38*F38*G38 -> 4.3591459e+08 | I38: 7.241163 | J38: =H38/I38 -> 60199528 | K38: 2635130 | L38: =J38/K38 -> 22.844993
A39: 2021 | B39: 4.0523046e+08 | C39: 1.0557501 | D39: 1.0638173 | E39: 1.1891497 | F39: 1.0929076 | G39: 1.0642523 | H39: =B39*D39*E39*F39*G39 -> 5.9625727e+08 | I39: 7.241163 | J39: =H39/I39 -> 82342750 | K39: 2595809 | L39: =J39/K39 -> 31.721421
A40: 2022 | B40: 4.6198645e+08 | C40: 1.0557501 | D40: 1.0638173 | E40: 1.1891497 | F40: 1.0929076 | G40: 1.0642523 | H40: =B40*D40*E40*F40*G40 -> 6.797682e+08 | I40: 7.241163 | J40: =H40/I40 -> 93875556 | K40: 2528654 | L40: =J40/K40 -> 37.124714
A41: 2023 | B41: 527221500 | C41: 1.0557501 | D41: 1.0638173 | E41: 1.1891497 | F41: 1.0929076 | G41: 1.0642523 | H41: =B41*G41 -> 5.6109667e+08 | I41: 7.241163 | J41: =H41/I41 -> 77487094 | K41: 2457783 | L41: =J41/K41 -> 31.527232
A42: 2024 | B42: 552520230 | C42: 1.0557501 | D42: 1.0638173 | E42: 1.1891497 | F42: 1.0929076 | G42: 1.0642523 | H42: =B42*D42*E42*F42*G42 -> 8.1297986e+08 | I42: 7.241163 | J42: =H42/I42 -> 1.12272e+08 | K42: 2402306 | L42: =J42/K42 -> 46.735096
A44: Ukraine
A45: Year | B45: Expenditure (Griven) | C45: 2019→2020 | D45: 2020→2021 | E45: 2021→2022 | F45: 2022→2023 | G45: 2023→2024 | H45: Inflated | I45: PPP factor | J45: PPP $ | K45: Population | L45: Adj for Population
...

Sheet OOP Exp.
A1: Out-of-pocket (OOP) Payments is a type of financing scheme where households pay out of their pocket for the medical service
A2: Country | B2: Latest Data Year | C2: OOP Expenditure as % of CHE | D2: Further Comments
A3: Afghanistan | B3: 2021 | C3: 77.2 | D3: The OOP data is taken from the 2021 National Health Accounts of Afghanistan (77.2%)
A4: Armenia | B4: 2023 | C4: 80 | D4: Cancer-specific OOP expenditure is also availble from the 2024 National Health Accounts of Armenia, which is 90.8% of the direct cancer expenditure. However, we used the GHED80% data for data comparability.
A5: Azerbaijan | B5: 2023 | C5: 65 | D5: GHED Data
A6: Belarus | B6: 2023 | C6: 28 | D6: GHED Data
A7: Estonia | B7: 2024 | C7: 21 | D7: GHED Data
A8: Georgia | B8: 2023 | C8: 59 | D8: GHED Data
A9: Kazakhstan | B9: 2023 | C9: 28 | D9: GHED Data
A10: Kyrgyzstan | B10: 2023 | C10: 42 | D10: GHED Data
A11: Latvia | B11: 2023 | C11: 35 | D11: GHED Data
A12: Lithuania | B12: 2024 | C12: 31 | D12: GHED Data
A13: Republic of Moldova | B13: 2023 | C13: 27 | D13: GHED Data
A14: Russian Federation | B14: 2023 | C14: 28 | D14: GHED Data
... A20: Uzbekistan | B20: 2023 | C20: 64 | D20: GHED Data

Sheet Per-Component Exp.
A1: Some countries either provided us or official reported expenditure per cancer component. For data comparability, we divide cancer expenditure into 3 components: screening, pharmaceuticals, and other medical services. "Other medical services" generally includes inpatient and outpatient cancer expenditure. For some countries, only pharmaceutical expenditure was available, while for others only screening expenditure was available. Here only GCHCFS expenditure is grasped. Only for Armenia, per-component expenditure also includes OOP.
B3: key | E3: Slovenia | F3: 2024 LCU | H3: Moldova | I3: 2024 LCU | K3: Georgia | L3: 2024, LCU | N3: Lithuania | O3: 2024, Mill LCU
B4: green - other medical services | E4: Screening | F4: 26840103 | H4: Hospital Care | I4: 406921280 | K4: Medication | L4: 1.5101192e+08 | N4: Screening | O4: 21.7
B5: blue - pharmaceuticals | E5: Other Medical Services | F5: 3.6059385e+08 | H5: Outpatient | I5: 51937260 | K5: Other Services | L5: 1.3313531e+08 | N5: Other Medical Services | O5: =O7-O6-O4 -> 182.8
B6: orange - screening | E6: Medicines | F6: 84322620 | H6: Expensive Medicines | I6: =(37087.46+28396.67)*1000 -> 65484130 | K6: Total | L6: 2.8414724e+08 | N6: Medicines | O6: 200
B7: LCU - Local Currency Units | E7: Total | F7: =SUM(F4:F6) -> 4.7175657e+08 | H7: Others | I7: =I9-SUM(I4:I6, I8) -> 28177560 | N7: Total | O7: 404.5
H8: Screening | I8: 4790500
H9: Total | I9: 557310730
B12: Estonia | C12: 2024 LCU | E12: Kazakhstan | F12: 2024 LCU | H12: Latvia | I12: 2024 LCU, not USD | K12: Armenia | L12: 2023, million LCU
B13: Screening | C13: 7511966 | E13: Prevention | F13: NA | H13: Medicines | I13: 74935312 | K13: Outpatient | L13: 1246
B14: Other Medical Services | C14: 243356243 | E14: Medicine | F14: =32847136193+23453652089 -> 56300788282 | H14: Outpatient | I14: 47543230 | K14: Inpatient | L14: 94225.4
B15: Pharmaceuticals | C15: 42146735 | E15: Other: | F15: NA | H15: Inpatient | I15: 47462478 | K15: Screening | L15: 83
B16: Total | C16: 293014944 | E16: Total | F16: 193938343000 | H16: Prevention | I16: 5789797 | K16: Pharamceuticals | L16: 14413.7
H17: Total before modeling | I17: =I13+I14+I15+I16 -> 1.7573082e+08 | K17: Others | L17: 10446.6
K18: Total | L18: 120414.6

Sheet Estonia, Slovakia
A1: Estonia, Longitudinal Per-Component Expenditure, NOT INFLATED | G1: Slovakia, Longitudinal Per-Cancer Diagnosis Expenditure, NOT INFLATED | M1: Slovakia, Linked-Series Deflator
A2: Year | B2: Medical care | C2: Pharmaceuticals | D2: Prevention | E2: Total | G2: ICD-10 (3-miestny) | H2: 2020 (EUR) | I2: 2021 (EUR) | J2: 2022 (EUR) | K2: 2023 (EUR) | M2: 2019→2020 | N2: 2020→2021 | O2: 2021→2022 | P2: 2022→2023 | Q2: 2023→2024
A3: 2020 | B3: 152295581 | C3: 26566576 | D3: 2622619 | E3: =B3+C3+D3 -> 181484776 | G3: C00 | H3: 285771.5 | I3: 289261.95 | J3: 222973.59 | K3: 332320.67 | M3: 1.0240778 | N3: 1.0224408 | O3: 1.0733388 | P3: 1.1002459 | Q3: 1.033937
A4: 2021 | B4: 158125494 | C4: 30239815 | D4: 3817270 | E4: =B4+C4+D4 -> 192182579 | G4: C01 | H4: 869926.62 | I4: 796621.3 | J4: 900284.67 | K4: 975474.92
A5: 2022 | B5: 171532296 | C5: 29443230 | D5: 4976000 | E5: =B5+C5+D5 -> 205951526 | G5: C02 | H5: 1653447.1 | I5: 1813791.3 | J5: 1917053.4 | K5: 1438564.2 | M5: The deflator was applied and the results were then plotted in R
A6: 2023 | B6: 211968849 | C6: 34580612 | D6: 6372104 | E6: =B6+C6+D6 -> 252921565 | G6: C03 | H6: 505115.86 | I6: 494150.63 | J6: 591809.9 | K6: 302209.99
A7: 2024 | B7: 243356243 | C7: 42146735 | D7: 7511966 | E7: =B7+C7+D7 -> 293014944 | G7: C04 | H7: 1186171.8 | I7: 1231535.6 | J7: 1256165 | K7: 1105795.6
A8: 2025 | B8: 265365332 | C8: 42980418 | D8: 8437053 | E8: =B8+C8+D8 -> 316782803 | G8: C05 | H8: 431376.12 | I8: 436087.42 | J8: 412797.93 | K8: 278222.58
G9: C06 | H9: 374701.76 | I9: 557086.76 | J9: 664260.07 | K9: 473727.19
A10: Estonia, Linked-Series Deflators | G10: C07 | H10: 335081.64 | I10: 347074.76 | J10: 425006.18 | K10: 378808.19
A11: 2020→2021 | B11: 2021→2022 | C11: 2022→2023 | D11: 2023→2024 | E11: 2023→2024 | G11: C08 | H11: 134292.42 | I11: 175104.85 | J11: 194422.28 | K11: 176641.82
A12: 1.0429149 | B12: 1.1684481 | C12: 1.0863528 | D12: 1.0398984 | E12: 1.0485205 | G12: C09 | H12: 1425245.8 | I12: 1646098.6 | J12: 1757787.7 | K12: 1710396.6
A13: 1.0429149 | B13: 1.1684481 | C13: 1.0863528 | D13: 1.0398984 | E13: 1.0485205 | G13: C10 | H13: 1539574.7 | I13: 1950231.8 | J13: 2047187.2 | K13: 1582947.8
A14: 1.0429149 | B14: 1.1684481 | C14: 1.0863528 | D14: 1.0398984 | E14: 1.0485205 | G14: C11 | H14: 397536.56 | I14: 564060.34 | J14: 517130.69 | K14: 485844.14
A15: 1.0429149 | B15: 1.1684481 | C15: 1.0863528 | D15: 1.0398984 | E15: 1.0485205 | G15: C12 | H15: 362049.99 | I15: 431055.01 | J15: 493117.43 | K15: 451681.77
A16: 1.0429149 | B16: 1.1684481 | C16: 1.0863528 | D16: 1.0398984 | E16: 1.0485205 | G16: C13 | H16: 1509823.3 | I16: 1612117 | J16: 1535047 | K16: 1430618.2
A17: 1.0429149 | B17: 1.1684481 | C17: 1.0863528 | D17: 1.0398984 | E17: 1.0485205 | G17: C14 | H17: 102254.17 | I17: 175658.85 | J17: 191357.29 | K17: 128206.04
A18: 1.0429149 | B18: 1.1684481 | C18: 1.0863528 | D18: 1.0398984 | E18: 1.0485205 | G18: C15 | H18: 2986516.3 | I18: 2784911.9 | J18: 3264818.2 | K18: 2030007.6
G19: C16 | H19: 7864503.5 | I19: 8935656 | J19: 8950174 | K19: 5743955.3
A20: Estonia, Inflated in Euro | G20: C17 | H20: 2643385.3 | I20: 3006810.6 | J20: 3179975.8 | K20: 2956113.5
A21: Year | B21: Medical care | C21: Pharmaceuticals | D21: Prevention | E21: Total | G21: C18 | H21: 22319802 | I21: 26036910 | J21: 27790646 | K21: 22135895
A22: 2020 | B22: =B3*A12*B12*C12*D12 -> 2.0965607e+08 | C22: =C3*A12*B12*C12*D12 -> 36572590 | D22: =D3*A12*B12*C12*D12 -> 3610400.1 | E22: =B22+C22+D22 -> 2.4983906e+08 | G22: C19 | H22: 5249539.9 | I22: 5985846.4 | J22: 6002308.7 | K22: 4645262.6
A23: 2021 | B23: =B4*B13*C13*D13 -> 2.0872436e+08 | C23: =C4*B13*C13*D13 -> 39916309 | D23: =D4*B13*C13*D13 -> 5038765.3 | E23: =B23+C23+D23 -> 2.5367944e+08 | G23: C20 | H23: 22773260 | I23: 26093432 | J23: 27115365 | K23: 22232747
A24: 2022 | B24: =B5*C14*D14 -> 1.9377945e+08 | C24: =C5*C14*D14 -> 33261917 | D24: =D5*C14*D14 -> 5621370.3 | E24: =B24+C24+D24 -> 2.3266274e+08 | G24: C21 | H24: 1006920.4 | I24: 1181640.3 | J24: 1150881 | K24: 758200.88
A25: 2023 | B25: =B6*D15 -> 2.2042608e+08 | C25: =C6*D15 -> 35960324 | D25: =D6*D15 -> 6626341 | E25: =B25+C25+D25 -> 2.6301274e+08 | G25: C22 | H25: 4248452.9 | I25: 5026091.1 | J25: 5119550.4 | K25: 4493477
A26: 2024 | B26: =B7 -> 243356243 | C26: 42146735 | D26: 7511966 | E26: =B26+C26+D26 -> 293014944 | G26: C23 | H26: 822649.66 | I26: 893701.12 | J26: 941004.28 | K26: 497744.05
A27: 2025 | B27: =265365332/1.04852053 -> 2.5308549e+08 | C27: =42980418/1.04852053 -> 40991489 | D27: =8437053/1.04852053 -> 8046626.4 | E27: =B27+C27+D27 -> 3.0212361e+08 | G27: C24 | H27: 1197978.2 | I27: 1440713.3 | J27: 1452921.1 | K27: 1025660.1
G28: C25 | H28: 8647902.7 | I28: 9516164 | J28: 10182525 | K28: 7242755.3
G29: C26 | H29: 326125.83 | I29: 344685.15 | J29: 300820.85 | K29: 234456.35
G30: C30 | H30: 200264.57 | I30: 303296.17 | J30: 277831.42 | K30: 250446.33
G31: C31 | H31: 273540.03 | I31: 242997.24 | J31: 254085.39 | K31: 247917.23
G32: C32 | H32: 2891309.1 | I32: 3162306.7 | J32: 3270725.4 | K32: 2200541.3
G33: C33 | H33: 54445.97 | I33: 61140.32 | J33: 76102.6 | K33: 33308.77
G34: C34 | H34: 26246439 | I34: 28241710 | J34: 31353506 | K34: 36713630
G35: C37 | H35: 128401 | I35: 210300.71 | J35: 220815.59 | K35: 154557.45
G36: C38 | H36: 501321.62 | I36: 508563.8 | J36: 491331.58 | K36: 270461.86
G37: C39 | H37: 99632.48 | I37: 58482.04 | J37: 39046.67 | K37: 43067.93
G38: C40 | H38: 1043461.2 | I38: 918584.76 | J38: 983100.41 | K38: 694289.27
G39: C41 | H39: 833117.3 | I39: 870734.59 | J39: 660818.93 | K39: 287514.5
... G92: Total | H92: 3.9797917e+08 | I92: 4.6176478e+08 | J92: 4.9886135e+08 | K92: 5.2442702e+08
